on_post_save_async called
on_post_save_async called
loading contents: /Users/cbono/Documents/code/codehealth/compare_ln.py
get_head_contents - compare_ln.py True
cmd: git show HEAD:compare_ln.py
Traceback (most recent call last):
  File "/Users/cbono/Library/Application Support/Sublime Text 3/Packages/User/codehealth.py", line 192, in setup
    self.get_head_contents(abs_file_name)
  File "/Users/cbono/Library/Application Support/Sublime Text 3/Packages/User/codehealth.py", line 211, in get_head_contents
    res = bash_command(head_cmd,self.f_dir)
  File "/Users/cbono/Library/Application Support/Sublime Text 3/Packages/User/codehealth.py", line 43, in bash_command
    return subprocess.check_output(cmd, cwd=folder,shell=True)
  File "./python3.3/subprocess.py", line 589, in check_output
subprocess.CalledProcessError: Command 'git show HEAD:compare_ln.py' returned non-zero exit status 128

<Comment left_bounds:(39, 19) right_bounds:(39, 87) score:100>
<Comment left_bounds:(104, 9) right_bounds:(104, 37) score:100>
loading contents: /Users/cbono/Documents/code/codehealth/log.txt
get_head_contents - log.txt False
setup successful
on_post_save_async called
loading contents: /Users/cbono/Documents/code/codehealth/compare.py
get_head_contents - compare.py True
cmd: git show HEAD:compare.py
setup successful
loading contents: /Users/cbono/Documents/code/codehealth/log.txt
get_head_contents - log.txt False
setup successful
on_post_save_async called
loading contents: /Users/cbono/Documents/code/codehealth/codehealth_ln.py
get_head_contents - codehealth_ln.py True
cmd: git show HEAD:codehealth_ln.py
setup successful
Traceback (most recent call last):
  File "/Users/cbono/Library/Application Support/Sublime Text 3/Packages/User/compare.py", line 69, in compare
    red2 = RedBaron(s2)
  File "/Library/Frameworks/Python.framework/Versions/3.5/lib/python3.5/site-packages/redbaron/redbaron.py", line 36, in __init__
    self.node_list = base_nodes.NodeList.from_fst(baron.parse(source_code), parent=self, on_attribute="root")
  File "/Library/Frameworks/Python.framework/Versions/3.5/lib/python3.5/site-packages/baron/baron.py", line 49, in parse
    tokens = tokenize(source_code, False)
  File "/Library/Frameworks/Python.framework/Versions/3.5/lib/python3.5/site-packages/baron/baron.py", line 70, in tokenize
    return mark_indentation(inner_group(space_group(_tokenize(group(split(pouet)), print_function))))
  File "/Library/Frameworks/Python.framework/Versions/3.5/lib/python3.5/site-packages/baron/inner_formatting_grouper.py", line 112, in group
    return list(group_generator(sequence))
  File "/Library/Frameworks/Python.framework/Versions/3.5/lib/python3.5/site-packages/baron/inner_formatting_grouper.py", line 189, in group_generator
    raise UnExpectedFormattingToken(debug_text)
baron.inner_formatting_grouper.UnExpectedFormattingToken: Unexpected 'space' token:

   1 /Users/cbono/Library/Application <--- here

Should have been grouped on either ('NAME', 'Application') (before) or ('NAME', 'Support') (after) token.

During handling of the above exception, another exception occurred:

Traceback (most recent call last):
  File "/Users/cbono/Library/Application Support/Sublime Text 3/Packages/User/codehealth.py", line 253, in render_health_scores
    #                 cs = compare(HealthCommand.last_file_contents, current_text)
  File "/Users/cbono/Library/Application Support/Sublime Text 3/Packages/User/compare.py", line 106, in compare
NameError: global name 'print_to_log' is not defined

loading contents: /Users/cbono/Documents/code/codehealth/log.txt
get_head_contents - log.txt False
setup successful
on_post_save_async called
loading contents: /Users/cbono/Documents/code/codehealth/codehealth_ln.py
get_head_contents - codehealth_ln.py True
cmd: git show HEAD:codehealth_ln.py
setup successful
Traceback (most recent call last):
  File "/Users/cbono/Library/Application Support/Sublime Text 3/Packages/User/compare.py", line 69, in compare
    red2 = RedBaron(s2)
  File "/Library/Frameworks/Python.framework/Versions/3.5/lib/python3.5/site-packages/redbaron/redbaron.py", line 36, in __init__
    self.node_list = base_nodes.NodeList.from_fst(baron.parse(source_code), parent=self, on_attribute="root")
  File "/Library/Frameworks/Python.framework/Versions/3.5/lib/python3.5/site-packages/baron/baron.py", line 49, in parse
    tokens = tokenize(source_code, False)
  File "/Library/Frameworks/Python.framework/Versions/3.5/lib/python3.5/site-packages/baron/baron.py", line 70, in tokenize
    return mark_indentation(inner_group(space_group(_tokenize(group(split(pouet)), print_function))))
  File "/Library/Frameworks/Python.framework/Versions/3.5/lib/python3.5/site-packages/baron/inner_formatting_grouper.py", line 112, in group
    return list(group_generator(sequence))
  File "/Library/Frameworks/Python.framework/Versions/3.5/lib/python3.5/site-packages/baron/inner_formatting_grouper.py", line 189, in group_generator
    raise UnExpectedFormattingToken(debug_text)
baron.inner_formatting_grouper.UnExpectedFormattingToken: Unexpected 'space' token:

   1 /Users/cbono/Library/Application <--- here

Should have been grouped on either ('NAME', 'Application') (before) or ('NAME', 'Support') (after) token.

During handling of the above exception, another exception occurred:

Traceback (most recent call last):
  File "/Users/cbono/Library/Application Support/Sublime Text 3/Packages/User/codehealth.py", line 253, in render_health_scores
    cs = compare(HealthCommand.last_file_contents, current_text)
  File "/Users/cbono/Library/Application Support/Sublime Text 3/Packages/User/compare.py", line 106, in compare
NameError: global name 'print_to_log' is not defined

loading contents: /Users/cbono/Documents/code/codehealth/log.txt
get_head_contents - log.txt False
setup successful
on_post_save_async called
loading contents: /Users/cbono/Documents/code/codehealth/codehealth_ln.py
get_head_contents - codehealth_ln.py True
cmd: git show HEAD:codehealth_ln.py
setup successful
Traceback (most recent call last):
  File "/Users/cbono/Library/Application Support/Sublime Text 3/Packages/User/compare.py", line 69, in compare
    red2 = RedBaron(s2)
  File "/Library/Frameworks/Python.framework/Versions/3.5/lib/python3.5/site-packages/redbaron/redbaron.py", line 36, in __init__
    self.node_list = base_nodes.NodeList.from_fst(baron.parse(source_code), parent=self, on_attribute="root")
  File "/Library/Frameworks/Python.framework/Versions/3.5/lib/python3.5/site-packages/baron/baron.py", line 49, in parse
    tokens = tokenize(source_code, False)
  File "/Library/Frameworks/Python.framework/Versions/3.5/lib/python3.5/site-packages/baron/baron.py", line 70, in tokenize
    return mark_indentation(inner_group(space_group(_tokenize(group(split(pouet)), print_function))))
  File "/Library/Frameworks/Python.framework/Versions/3.5/lib/python3.5/site-packages/baron/inner_formatting_grouper.py", line 112, in group
    return list(group_generator(sequence))
  File "/Library/Frameworks/Python.framework/Versions/3.5/lib/python3.5/site-packages/baron/inner_formatting_grouper.py", line 189, in group_generator
    raise UnExpectedFormattingToken(debug_text)
baron.inner_formatting_grouper.UnExpectedFormattingToken: Unexpected 'space' token:

   1 /Users/cbono/Library/Application <--- here

Should have been grouped on either ('NAME', 'Application') (before) or ('NAME', 'Support') (after) token.

During handling of the above exception, another exception occurred:

Traceback (most recent call last):
  File "/Users/cbono/Library/Application Support/Sublime Text 3/Packages/User/codehealth.py", line 253, in render_health_scores
    sublime.status_message("render_health, Error: " + str(e))
  File "/Users/cbono/Library/Application Support/Sublime Text 3/Packages/User/compare.py", line 106, in compare
NameError: global name 'print_to_log' is not defined

loading contents: /Users/cbono/Documents/code/codehealth/log.txt
get_head_contents - log.txt False
setup successful
on_post_save_async called
loading contents: /Users/cbono/Documents/code/codehealth/codehealth_ln.py
get_head_contents - codehealth_ln.py True
cmd: git show HEAD:codehealth_ln.py
setup successful
Traceback (most recent call last):
  File "/Users/cbono/Library/Application Support/Sublime Text 3/Packages/User/compare.py", line 69, in compare
    red2 = RedBaron(s2)
  File "/Library/Frameworks/Python.framework/Versions/3.5/lib/python3.5/site-packages/redbaron/redbaron.py", line 36, in __init__
    self.node_list = base_nodes.NodeList.from_fst(baron.parse(source_code), parent=self, on_attribute="root")
  File "/Library/Frameworks/Python.framework/Versions/3.5/lib/python3.5/site-packages/baron/baron.py", line 49, in parse
    tokens = tokenize(source_code, False)
  File "/Library/Frameworks/Python.framework/Versions/3.5/lib/python3.5/site-packages/baron/baron.py", line 70, in tokenize
    return mark_indentation(inner_group(space_group(_tokenize(group(split(pouet)), print_function))))
  File "/Library/Frameworks/Python.framework/Versions/3.5/lib/python3.5/site-packages/baron/inner_formatting_grouper.py", line 112, in group
    return list(group_generator(sequence))
  File "/Library/Frameworks/Python.framework/Versions/3.5/lib/python3.5/site-packages/baron/inner_formatting_grouper.py", line 189, in group_generator
    raise UnExpectedFormattingToken(debug_text)
baron.inner_formatting_grouper.UnExpectedFormattingToken: Unexpected 'space' token:

   1 /Users/cbono/Library/Application <--- here

Should have been grouped on either ('NAME', 'Application') (before) or ('NAME', 'Support') (after) token.

During handling of the above exception, another exception occurred:

Traceback (most recent call last):
  File "/Users/cbono/Library/Application Support/Sublime Text 3/Packages/User/codehealth.py", line 248, in render_health_scores
  File "/Users/cbono/Library/Application Support/Sublime Text 3/Packages/User/compare.py", line 106, in compare
NameError: global name 'print_to_log' is not defined

loading contents: /Users/cbono/Documents/code/codehealth/log.txt
get_head_contents - log.txt False
setup successful
on_post_save_async called
loading contents: /Users/cbono/Documents/code/codehealth/compare.py
get_head_contents - compare.py True
cmd: git show HEAD:compare.py
setup successful
<Comment left_bounds:(21, 9) right_bounds:(21, 18) score:100>
<Comment left_bounds:(27, 5) right_bounds:(27, 65) score:100>
<Comment left_bounds:(53, 19) right_bounds:(53, 80) score:100>
<Comment left_bounds:(116, 9) right_bounds:(116, 43) score:100>
loading contents: /Users/cbono/Documents/code/codehealth/log.txt
get_head_contents - log.txt False
setup successful
on_post_save_async called
loading contents: /Users/cbono/Documents/code/codehealth/compare.py
get_head_contents - compare.py True
cmd: git show HEAD:compare.py
setup successful
<Comment left_bounds:(39, 19) right_bounds:(39, 80) score:100>
loading contents: /Users/cbono/Documents/code/codehealth/log.txt
get_head_contents - log.txt False
setup successful
on_post_save_async called
loading contents: /Users/cbono/Documents/code/codehealth/compare_ln.py
get_head_contents - compare_ln.py True
cmd: git show HEAD:compare_ln.py
Traceback (most recent call last):
  File "/Users/cbono/Library/Application Support/Sublime Text 3/Packages/User/codehealth.py", line 184, in setup
    self.get_head_contents(abs_file_name)
  File "/Users/cbono/Library/Application Support/Sublime Text 3/Packages/User/codehealth.py", line 203, in get_head_contents
    res = bash_command(head_cmd,self.f_dir)
  File "/Users/cbono/Library/Application Support/Sublime Text 3/Packages/User/codehealth.py", line 43, in bash_command
    return subprocess.check_output(cmd, cwd=folder,shell=True)
  File "./python3.3/subprocess.py", line 589, in check_output
subprocess.CalledProcessError: Command 'git show HEAD:compare_ln.py' returned non-zero exit status 128

<Comment left_bounds:(134, 19) right_bounds:(134, 80) score:100>
Traceback (most recent call last):
  File "/Users/cbono/Library/Application Support/Sublime Text 3/Packages/User/compare.py", line 70, in compare
    #         result = []
  File "/Library/Frameworks/Python.framework/Versions/3.5/lib/python3.5/site-packages/redbaron/redbaron.py", line 36, in __init__
    self.node_list = base_nodes.NodeList.from_fst(baron.parse(source_code), parent=self, on_attribute="root")
  File "/Library/Frameworks/Python.framework/Versions/3.5/lib/python3.5/site-packages/baron/baron.py", line 49, in parse
    tokens = tokenize(source_code, False)
  File "/Library/Frameworks/Python.framework/Versions/3.5/lib/python3.5/site-packages/baron/baron.py", line 70, in tokenize
    return mark_indentation(inner_group(space_group(_tokenize(group(split(pouet)), print_function))))
  File "/Library/Frameworks/Python.framework/Versions/3.5/lib/python3.5/site-packages/baron/inner_formatting_grouper.py", line 112, in group
    return list(group_generator(sequence))
  File "/Library/Frameworks/Python.framework/Versions/3.5/lib/python3.5/site-packages/baron/inner_formatting_grouper.py", line 189, in group_generator
    raise UnExpectedFormattingToken(debug_text)
baron.inner_formatting_grouper.UnExpectedFormattingToken: Unexpected 'space' token:

   1 on_post_save_async <--- here

Should have been grouped on either ('NAME', 'on_post_save_async') (before) or ('NAME', 'called') (after) token.

During handling of the above exception, another exception occurred:

Traceback (most recent call last):
  File "/Users/cbono/Library/Application Support/Sublime Text 3/Packages/User/codehealth.py", line 245, in render_health_scores
    cs = compare(HealthCommand.last_file_contents, current_text)
  File "/Users/cbono/Library/Application Support/Sublime Text 3/Packages/User/compare.py", line 106, in compare
NameError: global name 'print_to_log' is not defined

Traceback (most recent call last):
  File "/Users/cbono/Library/Application Support/Sublime Text 3/Packages/User/compare.py", line 70, in compare
    #         result = []
  File "/Library/Frameworks/Python.framework/Versions/3.5/lib/python3.5/site-packages/redbaron/redbaron.py", line 36, in __init__
    self.node_list = base_nodes.NodeList.from_fst(baron.parse(source_code), parent=self, on_attribute="root")
  File "/Library/Frameworks/Python.framework/Versions/3.5/lib/python3.5/site-packages/baron/baron.py", line 49, in parse
    tokens = tokenize(source_code, False)
  File "/Library/Frameworks/Python.framework/Versions/3.5/lib/python3.5/site-packages/baron/baron.py", line 70, in tokenize
    return mark_indentation(inner_group(space_group(_tokenize(group(split(pouet)), print_function))))
  File "/Library/Frameworks/Python.framework/Versions/3.5/lib/python3.5/site-packages/baron/inner_formatting_grouper.py", line 112, in group
    return list(group_generator(sequence))
  File "/Library/Frameworks/Python.framework/Versions/3.5/lib/python3.5/site-packages/baron/inner_formatting_grouper.py", line 189, in group_generator
    raise UnExpectedFormattingToken(debug_text)
baron.inner_formatting_grouper.UnExpectedFormattingToken: Unexpected 'space' token:

   1 on_post_save_async <--- here

Should have been grouped on either ('NAME', 'on_post_save_async') (before) or ('NAME', 'called') (after) token.

During handling of the above exception, another exception occurred:

Traceback (most recent call last):
  File "/Users/cbono/Library/Application Support/Sublime Text 3/Packages/User/codehealth.py", line 245, in render_health_scores
    cs = compare(HealthCommand.last_file_contents, current_text)
  File "/Users/cbono/Library/Application Support/Sublime Text 3/Packages/User/compare.py", line 106, in compare
NameError: global name 'print_to_log' is not defined

Traceback (most recent call last):
  File "/Users/cbono/Library/Application Support/Sublime Text 3/Packages/User/compare.py", line 70, in compare
    #         result = []
  File "/Library/Frameworks/Python.framework/Versions/3.5/lib/python3.5/site-packages/redbaron/redbaron.py", line 36, in __init__
    self.node_list = base_nodes.NodeList.from_fst(baron.parse(source_code), parent=self, on_attribute="root")
  File "/Library/Frameworks/Python.framework/Versions/3.5/lib/python3.5/site-packages/baron/baron.py", line 49, in parse
    tokens = tokenize(source_code, False)
  File "/Library/Frameworks/Python.framework/Versions/3.5/lib/python3.5/site-packages/baron/baron.py", line 70, in tokenize
    return mark_indentation(inner_group(space_group(_tokenize(group(split(pouet)), print_function))))
  File "/Library/Frameworks/Python.framework/Versions/3.5/lib/python3.5/site-packages/baron/inner_formatting_grouper.py", line 112, in group
    return list(group_generator(sequence))
  File "/Library/Frameworks/Python.framework/Versions/3.5/lib/python3.5/site-packages/baron/inner_formatting_grouper.py", line 189, in group_generator
    raise UnExpectedFormattingToken(debug_text)
baron.inner_formatting_grouper.UnExpectedFormattingToken: Unexpected 'space' token:

   1 on_post_save_async <--- here

Should have been grouped on either ('NAME', 'on_post_save_async') (before) or ('NAME', 'called') (after) token.

During handling of the above exception, another exception occurred:

Traceback (most recent call last):
  File "/Users/cbono/Library/Application Support/Sublime Text 3/Packages/User/codehealth.py", line 245, in render_health_scores
    cs = compare(HealthCommand.last_file_contents, current_text)
  File "/Users/cbono/Library/Application Support/Sublime Text 3/Packages/User/compare.py", line 106, in compare
NameError: global name 'print_to_log' is not defined

Traceback (most recent call last):
  File "/Users/cbono/Library/Application Support/Sublime Text 3/Packages/User/compare.py", line 70, in compare
    #         result = []
  File "/Library/Frameworks/Python.framework/Versions/3.5/lib/python3.5/site-packages/redbaron/redbaron.py", line 36, in __init__
    self.node_list = base_nodes.NodeList.from_fst(baron.parse(source_code), parent=self, on_attribute="root")
  File "/Library/Frameworks/Python.framework/Versions/3.5/lib/python3.5/site-packages/baron/baron.py", line 49, in parse
    tokens = tokenize(source_code, False)
  File "/Library/Frameworks/Python.framework/Versions/3.5/lib/python3.5/site-packages/baron/baron.py", line 70, in tokenize
    return mark_indentation(inner_group(space_group(_tokenize(group(split(pouet)), print_function))))
  File "/Library/Frameworks/Python.framework/Versions/3.5/lib/python3.5/site-packages/baron/inner_formatting_grouper.py", line 112, in group
    return list(group_generator(sequence))
  File "/Library/Frameworks/Python.framework/Versions/3.5/lib/python3.5/site-packages/baron/inner_formatting_grouper.py", line 189, in group_generator
    raise UnExpectedFormattingToken(debug_text)
baron.inner_formatting_grouper.UnExpectedFormattingToken: Unexpected 'space' token:

   1 on_post_save_async <--- here

Should have been grouped on either ('NAME', 'on_post_save_async') (before) or ('NAME', 'called') (after) token.

During handling of the above exception, another exception occurred:

Traceback (most recent call last):
  File "/Users/cbono/Library/Application Support/Sublime Text 3/Packages/User/codehealth.py", line 245, in render_health_scores
    cs = compare(HealthCommand.last_file_contents, current_text)
  File "/Users/cbono/Library/Application Support/Sublime Text 3/Packages/User/compare.py", line 106, in compare
NameError: global name 'print_to_log' is not defined

Traceback (most recent call last):
  File "/Users/cbono/Library/Application Support/Sublime Text 3/Packages/User/compare.py", line 70, in compare
    #         result = []
  File "/Library/Frameworks/Python.framework/Versions/3.5/lib/python3.5/site-packages/redbaron/redbaron.py", line 36, in __init__
    self.node_list = base_nodes.NodeList.from_fst(baron.parse(source_code), parent=self, on_attribute="root")
  File "/Library/Frameworks/Python.framework/Versions/3.5/lib/python3.5/site-packages/baron/baron.py", line 49, in parse
    tokens = tokenize(source_code, False)
  File "/Library/Frameworks/Python.framework/Versions/3.5/lib/python3.5/site-packages/baron/baron.py", line 70, in tokenize
    return mark_indentation(inner_group(space_group(_tokenize(group(split(pouet)), print_function))))
  File "/Library/Frameworks/Python.framework/Versions/3.5/lib/python3.5/site-packages/baron/inner_formatting_grouper.py", line 112, in group
    return list(group_generator(sequence))
  File "/Library/Frameworks/Python.framework/Versions/3.5/lib/python3.5/site-packages/baron/inner_formatting_grouper.py", line 189, in group_generator
    raise UnExpectedFormattingToken(debug_text)
baron.inner_formatting_grouper.UnExpectedFormattingToken: Unexpected 'space' token:

   1 on_post_save_async <--- here

Should have been grouped on either ('NAME', 'on_post_save_async') (before) or ('NAME', 'called') (after) token.

During handling of the above exception, another exception occurred:

Traceback (most recent call last):
  File "/Users/cbono/Library/Application Support/Sublime Text 3/Packages/User/codehealth.py", line 245, in render_health_scores
    cs = compare(HealthCommand.last_file_contents, current_text)
  File "/Users/cbono/Library/Application Support/Sublime Text 3/Packages/User/compare.py", line 106, in compare
NameError: global name 'print_to_log' is not defined

Traceback (most recent call last):
  File "/Users/cbono/Library/Application Support/Sublime Text 3/Packages/User/compare.py", line 70, in compare
    #         result = []
  File "/Library/Frameworks/Python.framework/Versions/3.5/lib/python3.5/site-packages/redbaron/redbaron.py", line 36, in __init__
    self.node_list = base_nodes.NodeList.from_fst(baron.parse(source_code), parent=self, on_attribute="root")
  File "/Library/Frameworks/Python.framework/Versions/3.5/lib/python3.5/site-packages/baron/baron.py", line 49, in parse
    tokens = tokenize(source_code, False)
  File "/Library/Frameworks/Python.framework/Versions/3.5/lib/python3.5/site-packages/baron/baron.py", line 70, in tokenize
    return mark_indentation(inner_group(space_group(_tokenize(group(split(pouet)), print_function))))
  File "/Library/Frameworks/Python.framework/Versions/3.5/lib/python3.5/site-packages/baron/inner_formatting_grouper.py", line 112, in group
    return list(group_generator(sequence))
  File "/Library/Frameworks/Python.framework/Versions/3.5/lib/python3.5/site-packages/baron/inner_formatting_grouper.py", line 189, in group_generator
    raise UnExpectedFormattingToken(debug_text)
baron.inner_formatting_grouper.UnExpectedFormattingToken: Unexpected 'space' token:

   1 on_post_save_async <--- here

Should have been grouped on either ('NAME', 'on_post_save_async') (before) or ('NAME', 'called') (after) token.

During handling of the above exception, another exception occurred:

Traceback (most recent call last):
  File "/Users/cbono/Library/Application Support/Sublime Text 3/Packages/User/codehealth.py", line 245, in render_health_scores
    cs = compare(HealthCommand.last_file_contents, current_text)
  File "/Users/cbono/Library/Application Support/Sublime Text 3/Packages/User/compare.py", line 106, in compare
NameError: global name 'print_to_log' is not defined

Traceback (most recent call last):
  File "/Users/cbono/Library/Application Support/Sublime Text 3/Packages/User/compare.py", line 70, in compare
    #         result = []
  File "/Library/Frameworks/Python.framework/Versions/3.5/lib/python3.5/site-packages/redbaron/redbaron.py", line 36, in __init__
    self.node_list = base_nodes.NodeList.from_fst(baron.parse(source_code), parent=self, on_attribute="root")
  File "/Library/Frameworks/Python.framework/Versions/3.5/lib/python3.5/site-packages/baron/baron.py", line 49, in parse
    tokens = tokenize(source_code, False)
  File "/Library/Frameworks/Python.framework/Versions/3.5/lib/python3.5/site-packages/baron/baron.py", line 70, in tokenize
    return mark_indentation(inner_group(space_group(_tokenize(group(split(pouet)), print_function))))
  File "/Library/Frameworks/Python.framework/Versions/3.5/lib/python3.5/site-packages/baron/inner_formatting_grouper.py", line 112, in group
    return list(group_generator(sequence))
  File "/Library/Frameworks/Python.framework/Versions/3.5/lib/python3.5/site-packages/baron/inner_formatting_grouper.py", line 189, in group_generator
    raise UnExpectedFormattingToken(debug_text)
baron.inner_formatting_grouper.UnExpectedFormattingToken: Unexpected 'space' token:

   1 on_post_save_async <--- here

Should have been grouped on either ('NAME', 'on_post_save_async') (before) or ('NAME', 'called') (after) token.

During handling of the above exception, another exception occurred:

Traceback (most recent call last):
  File "/Users/cbono/Library/Application Support/Sublime Text 3/Packages/User/codehealth.py", line 245, in render_health_scores
    cs = compare(HealthCommand.last_file_contents, current_text)
  File "/Users/cbono/Library/Application Support/Sublime Text 3/Packages/User/compare.py", line 106, in compare
NameError: global name 'print_to_log' is not defined

Traceback (most recent call last):
  File "/Users/cbono/Library/Application Support/Sublime Text 3/Packages/User/compare.py", line 70, in compare
    #         result = []
  File "/Library/Frameworks/Python.framework/Versions/3.5/lib/python3.5/site-packages/redbaron/redbaron.py", line 36, in __init__
    self.node_list = base_nodes.NodeList.from_fst(baron.parse(source_code), parent=self, on_attribute="root")
  File "/Library/Frameworks/Python.framework/Versions/3.5/lib/python3.5/site-packages/baron/baron.py", line 49, in parse
    tokens = tokenize(source_code, False)
  File "/Library/Frameworks/Python.framework/Versions/3.5/lib/python3.5/site-packages/baron/baron.py", line 70, in tokenize
    return mark_indentation(inner_group(space_group(_tokenize(group(split(pouet)), print_function))))
  File "/Library/Frameworks/Python.framework/Versions/3.5/lib/python3.5/site-packages/baron/inner_formatting_grouper.py", line 112, in group
    return list(group_generator(sequence))
  File "/Library/Frameworks/Python.framework/Versions/3.5/lib/python3.5/site-packages/baron/inner_formatting_grouper.py", line 189, in group_generator
    raise UnExpectedFormattingToken(debug_text)
baron.inner_formatting_grouper.UnExpectedFormattingToken: Unexpected 'space' token:

   1 on_post_save_async <--- here

Should have been grouped on either ('NAME', 'on_post_save_async') (before) or ('NAME', 'called') (after) token.

During handling of the above exception, another exception occurred:

Traceback (most recent call last):
  File "/Users/cbono/Library/Application Support/Sublime Text 3/Packages/User/codehealth.py", line 245, in render_health_scores
    cs = compare(HealthCommand.last_file_contents, current_text)
  File "/Users/cbono/Library/Application Support/Sublime Text 3/Packages/User/compare.py", line 106, in compare
NameError: global name 'print_to_log' is not defined

on_post_save_async called
loading contents: /Users/cbono/Documents/code/codehealth/compare_ln.py
get_head_contents - compare_ln.py True
cmd: git show HEAD:compare_ln.py
Traceback (most recent call last):
  File "/Users/cbono/Library/Application Support/Sublime Text 3/Packages/User/codehealth.py", line 184, in setup
    self.get_head_contents(abs_file_name)
  File "/Users/cbono/Library/Application Support/Sublime Text 3/Packages/User/codehealth.py", line 203, in get_head_contents
    res = bash_command(head_cmd,self.f_dir)
  File "/Users/cbono/Library/Application Support/Sublime Text 3/Packages/User/codehealth.py", line 43, in bash_command
    return subprocess.check_output(cmd, cwd=folder,shell=True)
  File "./python3.3/subprocess.py", line 589, in check_output
subprocess.CalledProcessError: Command 'git show HEAD:compare_ln.py' returned non-zero exit status 128

<Comment left_bounds:(39, 19) right_bounds:(39, 87) score:100>
<Comment left_bounds:(104, 9) right_bounds:(104, 37) score:100>
loading contents: /Users/cbono/Documents/code/codehealth/log.txt
get_head_contents - log.txt False
setup successful
on_post_save_async called
loading contents: /Users/cbono/Documents/code/codehealth/compare_ln.py
get_head_contents - compare_ln.py True
cmd: git show HEAD:compare_ln.py
Traceback (most recent call last):
  File "/Users/cbono/Library/Application Support/Sublime Text 3/Packages/User/codehealth.py", line 184, in setup
    self.get_head_contents(abs_file_name)
  File "/Users/cbono/Library/Application Support/Sublime Text 3/Packages/User/codehealth.py", line 203, in get_head_contents
    res = bash_command(head_cmd,self.f_dir)
  File "/Users/cbono/Library/Application Support/Sublime Text 3/Packages/User/codehealth.py", line 43, in bash_command
    return subprocess.check_output(cmd, cwd=folder,shell=True)
  File "./python3.3/subprocess.py", line 589, in check_output
subprocess.CalledProcessError: Command 'git show HEAD:compare_ln.py' returned non-zero exit status 128

<Comment left_bounds:(46, 19) right_bounds:(46, 87) score:100>
<Comment left_bounds:(111, 9) right_bounds:(111, 37) score:100>
Traceback (most recent call last):
  File "/Users/cbono/Library/Application Support/Sublime Text 3/Packages/User/compare.py", line 70, in compare
  File "/Library/Frameworks/Python.framework/Versions/3.5/lib/python3.5/site-packages/redbaron/redbaron.py", line 36, in __init__
    self.node_list = base_nodes.NodeList.from_fst(baron.parse(source_code), parent=self, on_attribute="root")
  File "/Library/Frameworks/Python.framework/Versions/3.5/lib/python3.5/site-packages/baron/baron.py", line 49, in parse
    tokens = tokenize(source_code, False)
  File "/Library/Frameworks/Python.framework/Versions/3.5/lib/python3.5/site-packages/baron/baron.py", line 70, in tokenize
    return mark_indentation(inner_group(space_group(_tokenize(group(split(pouet)), print_function))))
  File "/Library/Frameworks/Python.framework/Versions/3.5/lib/python3.5/site-packages/baron/inner_formatting_grouper.py", line 112, in group
    return list(group_generator(sequence))
  File "/Library/Frameworks/Python.framework/Versions/3.5/lib/python3.5/site-packages/baron/inner_formatting_grouper.py", line 189, in group_generator
    raise UnExpectedFormattingToken(debug_text)
baron.inner_formatting_grouper.UnExpectedFormattingToken: Unexpected 'space' token:

   1 on_post_save_async <--- here

Should have been grouped on either ('NAME', 'on_post_save_async') (before) or ('NAME', 'called') (after) token.

During handling of the above exception, another exception occurred:

Traceback (most recent call last):
  File "/Users/cbono/Library/Application Support/Sublime Text 3/Packages/User/codehealth.py", line 245, in render_health_scores
    cs = compare(HealthCommand.last_file_contents, current_text)
  File "/Users/cbono/Library/Application Support/Sublime Text 3/Packages/User/compare.py", line 106, in compare
    result = [r for r in result if r != []]
NameError: global name 'print_to_log' is not defined

Traceback (most recent call last):
  File "/Users/cbono/Library/Application Support/Sublime Text 3/Packages/User/compare.py", line 70, in compare
  File "/Library/Frameworks/Python.framework/Versions/3.5/lib/python3.5/site-packages/redbaron/redbaron.py", line 36, in __init__
    self.node_list = base_nodes.NodeList.from_fst(baron.parse(source_code), parent=self, on_attribute="root")
  File "/Library/Frameworks/Python.framework/Versions/3.5/lib/python3.5/site-packages/baron/baron.py", line 49, in parse
    tokens = tokenize(source_code, False)
  File "/Library/Frameworks/Python.framework/Versions/3.5/lib/python3.5/site-packages/baron/baron.py", line 70, in tokenize
    return mark_indentation(inner_group(space_group(_tokenize(group(split(pouet)), print_function))))
  File "/Library/Frameworks/Python.framework/Versions/3.5/lib/python3.5/site-packages/baron/inner_formatting_grouper.py", line 112, in group
    return list(group_generator(sequence))
  File "/Library/Frameworks/Python.framework/Versions/3.5/lib/python3.5/site-packages/baron/inner_formatting_grouper.py", line 189, in group_generator
    raise UnExpectedFormattingToken(debug_text)
baron.inner_formatting_grouper.UnExpectedFormattingToken: Unexpected 'space' token:

   1 on_post_save_async <--- here

Should have been grouped on either ('NAME', 'on_post_save_async') (before) or ('NAME', 'called') (after) token.

During handling of the above exception, another exception occurred:

Traceback (most recent call last):
  File "/Users/cbono/Library/Application Support/Sublime Text 3/Packages/User/codehealth.py", line 245, in render_health_scores
    cs = compare(HealthCommand.last_file_contents, current_text)
  File "/Users/cbono/Library/Application Support/Sublime Text 3/Packages/User/compare.py", line 106, in compare
    result = [r for r in result if r != []]
NameError: global name 'print_to_log' is not defined

Traceback (most recent call last):
  File "/Users/cbono/Library/Application Support/Sublime Text 3/Packages/User/compare.py", line 70, in compare
  File "/Library/Frameworks/Python.framework/Versions/3.5/lib/python3.5/site-packages/redbaron/redbaron.py", line 36, in __init__
    self.node_list = base_nodes.NodeList.from_fst(baron.parse(source_code), parent=self, on_attribute="root")
  File "/Library/Frameworks/Python.framework/Versions/3.5/lib/python3.5/site-packages/baron/baron.py", line 49, in parse
    tokens = tokenize(source_code, False)
  File "/Library/Frameworks/Python.framework/Versions/3.5/lib/python3.5/site-packages/baron/baron.py", line 70, in tokenize
    return mark_indentation(inner_group(space_group(_tokenize(group(split(pouet)), print_function))))
  File "/Library/Frameworks/Python.framework/Versions/3.5/lib/python3.5/site-packages/baron/inner_formatting_grouper.py", line 112, in group
    return list(group_generator(sequence))
  File "/Library/Frameworks/Python.framework/Versions/3.5/lib/python3.5/site-packages/baron/inner_formatting_grouper.py", line 189, in group_generator
    raise UnExpectedFormattingToken(debug_text)
baron.inner_formatting_grouper.UnExpectedFormattingToken: Unexpected 'space' token:

   1 on_post_save_async <--- here

Should have been grouped on either ('NAME', 'on_post_save_async') (before) or ('NAME', 'called') (after) token.

During handling of the above exception, another exception occurred:

Traceback (most recent call last):
  File "/Users/cbono/Library/Application Support/Sublime Text 3/Packages/User/codehealth.py", line 245, in render_health_scores
    cs = compare(HealthCommand.last_file_contents, current_text)
  File "/Users/cbono/Library/Application Support/Sublime Text 3/Packages/User/compare.py", line 106, in compare
    result = [r for r in result if r != []]
NameError: global name 'print_to_log' is not defined

Traceback (most recent call last):
  File "/Users/cbono/Library/Application Support/Sublime Text 3/Packages/User/compare.py", line 70, in compare
  File "/Library/Frameworks/Python.framework/Versions/3.5/lib/python3.5/site-packages/redbaron/redbaron.py", line 36, in __init__
    self.node_list = base_nodes.NodeList.from_fst(baron.parse(source_code), parent=self, on_attribute="root")
  File "/Library/Frameworks/Python.framework/Versions/3.5/lib/python3.5/site-packages/baron/baron.py", line 49, in parse
    tokens = tokenize(source_code, False)
  File "/Library/Frameworks/Python.framework/Versions/3.5/lib/python3.5/site-packages/baron/baron.py", line 70, in tokenize
    return mark_indentation(inner_group(space_group(_tokenize(group(split(pouet)), print_function))))
  File "/Library/Frameworks/Python.framework/Versions/3.5/lib/python3.5/site-packages/baron/inner_formatting_grouper.py", line 112, in group
    return list(group_generator(sequence))
  File "/Library/Frameworks/Python.framework/Versions/3.5/lib/python3.5/site-packages/baron/inner_formatting_grouper.py", line 189, in group_generator
    raise UnExpectedFormattingToken(debug_text)
baron.inner_formatting_grouper.UnExpectedFormattingToken: Unexpected 'space' token:

   1 on_post_save_async <--- here

Should have been grouped on either ('NAME', 'on_post_save_async') (before) or ('NAME', 'called') (after) token.

During handling of the above exception, another exception occurred:

Traceback (most recent call last):
  File "/Users/cbono/Library/Application Support/Sublime Text 3/Packages/User/codehealth.py", line 245, in render_health_scores
    cs = compare(HealthCommand.last_file_contents, current_text)
  File "/Users/cbono/Library/Application Support/Sublime Text 3/Packages/User/compare.py", line 106, in compare
    result = [r for r in result if r != []]
NameError: global name 'print_to_log' is not defined

Traceback (most recent call last):
  File "/Users/cbono/Library/Application Support/Sublime Text 3/Packages/User/compare.py", line 70, in compare
  File "/Library/Frameworks/Python.framework/Versions/3.5/lib/python3.5/site-packages/redbaron/redbaron.py", line 36, in __init__
    self.node_list = base_nodes.NodeList.from_fst(baron.parse(source_code), parent=self, on_attribute="root")
  File "/Library/Frameworks/Python.framework/Versions/3.5/lib/python3.5/site-packages/baron/baron.py", line 49, in parse
    tokens = tokenize(source_code, False)
  File "/Library/Frameworks/Python.framework/Versions/3.5/lib/python3.5/site-packages/baron/baron.py", line 70, in tokenize
    return mark_indentation(inner_group(space_group(_tokenize(group(split(pouet)), print_function))))
  File "/Library/Frameworks/Python.framework/Versions/3.5/lib/python3.5/site-packages/baron/inner_formatting_grouper.py", line 112, in group
    return list(group_generator(sequence))
  File "/Library/Frameworks/Python.framework/Versions/3.5/lib/python3.5/site-packages/baron/inner_formatting_grouper.py", line 189, in group_generator
    raise UnExpectedFormattingToken(debug_text)
baron.inner_formatting_grouper.UnExpectedFormattingToken: Unexpected 'space' token:

   1 on_post_save_async <--- here

Should have been grouped on either ('NAME', 'on_post_save_async') (before) or ('NAME', 'called') (after) token.

During handling of the above exception, another exception occurred:

Traceback (most recent call last):
  File "/Users/cbono/Library/Application Support/Sublime Text 3/Packages/User/codehealth.py", line 245, in render_health_scores
    cs = compare(HealthCommand.last_file_contents, current_text)
  File "/Users/cbono/Library/Application Support/Sublime Text 3/Packages/User/compare.py", line 106, in compare
    result = [r for r in result if r != []]
NameError: global name 'print_to_log' is not defined

Traceback (most recent call last):
  File "/Users/cbono/Library/Application Support/Sublime Text 3/Packages/User/compare.py", line 70, in compare
  File "/Library/Frameworks/Python.framework/Versions/3.5/lib/python3.5/site-packages/redbaron/redbaron.py", line 36, in __init__
    self.node_list = base_nodes.NodeList.from_fst(baron.parse(source_code), parent=self, on_attribute="root")
  File "/Library/Frameworks/Python.framework/Versions/3.5/lib/python3.5/site-packages/baron/baron.py", line 49, in parse
    tokens = tokenize(source_code, False)
  File "/Library/Frameworks/Python.framework/Versions/3.5/lib/python3.5/site-packages/baron/baron.py", line 70, in tokenize
    return mark_indentation(inner_group(space_group(_tokenize(group(split(pouet)), print_function))))
  File "/Library/Frameworks/Python.framework/Versions/3.5/lib/python3.5/site-packages/baron/inner_formatting_grouper.py", line 112, in group
    return list(group_generator(sequence))
  File "/Library/Frameworks/Python.framework/Versions/3.5/lib/python3.5/site-packages/baron/inner_formatting_grouper.py", line 189, in group_generator
    raise UnExpectedFormattingToken(debug_text)
baron.inner_formatting_grouper.UnExpectedFormattingToken: Unexpected 'space' token:

   1 on_post_save_async <--- here

Should have been grouped on either ('NAME', 'on_post_save_async') (before) or ('NAME', 'called') (after) token.

During handling of the above exception, another exception occurred:

Traceback (most recent call last):
  File "/Users/cbono/Library/Application Support/Sublime Text 3/Packages/User/codehealth.py", line 245, in render_health_scores
    cs = compare(HealthCommand.last_file_contents, current_text)
  File "/Users/cbono/Library/Application Support/Sublime Text 3/Packages/User/compare.py", line 106, in compare
    result = [r for r in result if r != []]
NameError: global name 'print_to_log' is not defined

Traceback (most recent call last):
  File "/Users/cbono/Library/Application Support/Sublime Text 3/Packages/User/compare.py", line 70, in compare
  File "/Library/Frameworks/Python.framework/Versions/3.5/lib/python3.5/site-packages/redbaron/redbaron.py", line 36, in __init__
    self.node_list = base_nodes.NodeList.from_fst(baron.parse(source_code), parent=self, on_attribute="root")
  File "/Library/Frameworks/Python.framework/Versions/3.5/lib/python3.5/site-packages/baron/baron.py", line 49, in parse
    tokens = tokenize(source_code, False)
  File "/Library/Frameworks/Python.framework/Versions/3.5/lib/python3.5/site-packages/baron/baron.py", line 70, in tokenize
    return mark_indentation(inner_group(space_group(_tokenize(group(split(pouet)), print_function))))
  File "/Library/Frameworks/Python.framework/Versions/3.5/lib/python3.5/site-packages/baron/inner_formatting_grouper.py", line 112, in group
    return list(group_generator(sequence))
  File "/Library/Frameworks/Python.framework/Versions/3.5/lib/python3.5/site-packages/baron/inner_formatting_grouper.py", line 189, in group_generator
    raise UnExpectedFormattingToken(debug_text)
baron.inner_formatting_grouper.UnExpectedFormattingToken: Unexpected 'space' token:

   1 on_post_save_async <--- here

Should have been grouped on either ('NAME', 'on_post_save_async') (before) or ('NAME', 'called') (after) token.

During handling of the above exception, another exception occurred:

Traceback (most recent call last):
  File "/Users/cbono/Library/Application Support/Sublime Text 3/Packages/User/codehealth.py", line 245, in render_health_scores
    cs = compare(HealthCommand.last_file_contents, current_text)
  File "/Users/cbono/Library/Application Support/Sublime Text 3/Packages/User/compare.py", line 106, in compare
    result = [r for r in result if r != []]
NameError: global name 'print_to_log' is not defined

Traceback (most recent call last):
  File "/Users/cbono/Library/Application Support/Sublime Text 3/Packages/User/compare.py", line 70, in compare
  File "/Library/Frameworks/Python.framework/Versions/3.5/lib/python3.5/site-packages/redbaron/redbaron.py", line 36, in __init__
    self.node_list = base_nodes.NodeList.from_fst(baron.parse(source_code), parent=self, on_attribute="root")
  File "/Library/Frameworks/Python.framework/Versions/3.5/lib/python3.5/site-packages/baron/baron.py", line 49, in parse
    tokens = tokenize(source_code, False)
  File "/Library/Frameworks/Python.framework/Versions/3.5/lib/python3.5/site-packages/baron/baron.py", line 70, in tokenize
    return mark_indentation(inner_group(space_group(_tokenize(group(split(pouet)), print_function))))
  File "/Library/Frameworks/Python.framework/Versions/3.5/lib/python3.5/site-packages/baron/inner_formatting_grouper.py", line 112, in group
    return list(group_generator(sequence))
  File "/Library/Frameworks/Python.framework/Versions/3.5/lib/python3.5/site-packages/baron/inner_formatting_grouper.py", line 189, in group_generator
    raise UnExpectedFormattingToken(debug_text)
baron.inner_formatting_grouper.UnExpectedFormattingToken: Unexpected 'space' token:

   1 on_post_save_async <--- here

Should have been grouped on either ('NAME', 'on_post_save_async') (before) or ('NAME', 'called') (after) token.

During handling of the above exception, another exception occurred:

Traceback (most recent call last):
  File "/Users/cbono/Library/Application Support/Sublime Text 3/Packages/User/codehealth.py", line 245, in render_health_scores
    cs = compare(HealthCommand.last_file_contents, current_text)
  File "/Users/cbono/Library/Application Support/Sublime Text 3/Packages/User/compare.py", line 106, in compare
    result = [r for r in result if r != []]
NameError: global name 'print_to_log' is not defined

Traceback (most recent call last):
  File "/Users/cbono/Library/Application Support/Sublime Text 3/Packages/User/compare.py", line 70, in compare
  File "/Library/Frameworks/Python.framework/Versions/3.5/lib/python3.5/site-packages/redbaron/redbaron.py", line 36, in __init__
    self.node_list = base_nodes.NodeList.from_fst(baron.parse(source_code), parent=self, on_attribute="root")
  File "/Library/Frameworks/Python.framework/Versions/3.5/lib/python3.5/site-packages/baron/baron.py", line 49, in parse
    tokens = tokenize(source_code, False)
  File "/Library/Frameworks/Python.framework/Versions/3.5/lib/python3.5/site-packages/baron/baron.py", line 70, in tokenize
    return mark_indentation(inner_group(space_group(_tokenize(group(split(pouet)), print_function))))
  File "/Library/Frameworks/Python.framework/Versions/3.5/lib/python3.5/site-packages/baron/inner_formatting_grouper.py", line 112, in group
    return list(group_generator(sequence))
  File "/Library/Frameworks/Python.framework/Versions/3.5/lib/python3.5/site-packages/baron/inner_formatting_grouper.py", line 189, in group_generator
    raise UnExpectedFormattingToken(debug_text)
baron.inner_formatting_grouper.UnExpectedFormattingToken: Unexpected 'space' token:

   1 on_post_save_async <--- here

Should have been grouped on either ('NAME', 'on_post_save_async') (before) or ('NAME', 'called') (after) token.

During handling of the above exception, another exception occurred:

Traceback (most recent call last):
  File "/Users/cbono/Library/Application Support/Sublime Text 3/Packages/User/codehealth.py", line 245, in render_health_scores
    cs = compare(HealthCommand.last_file_contents, current_text)
  File "/Users/cbono/Library/Application Support/Sublime Text 3/Packages/User/compare.py", line 106, in compare
    result = [r for r in result if r != []]
NameError: global name 'print_to_log' is not defined

Traceback (most recent call last):
  File "/Users/cbono/Library/Application Support/Sublime Text 3/Packages/User/compare.py", line 70, in compare
  File "/Library/Frameworks/Python.framework/Versions/3.5/lib/python3.5/site-packages/redbaron/redbaron.py", line 36, in __init__
    self.node_list = base_nodes.NodeList.from_fst(baron.parse(source_code), parent=self, on_attribute="root")
  File "/Library/Frameworks/Python.framework/Versions/3.5/lib/python3.5/site-packages/baron/baron.py", line 49, in parse
    tokens = tokenize(source_code, False)
  File "/Library/Frameworks/Python.framework/Versions/3.5/lib/python3.5/site-packages/baron/baron.py", line 70, in tokenize
    return mark_indentation(inner_group(space_group(_tokenize(group(split(pouet)), print_function))))
  File "/Library/Frameworks/Python.framework/Versions/3.5/lib/python3.5/site-packages/baron/inner_formatting_grouper.py", line 112, in group
    return list(group_generator(sequence))
  File "/Library/Frameworks/Python.framework/Versions/3.5/lib/python3.5/site-packages/baron/inner_formatting_grouper.py", line 189, in group_generator
    raise UnExpectedFormattingToken(debug_text)
baron.inner_formatting_grouper.UnExpectedFormattingToken: Unexpected 'space' token:

   1 on_post_save_async <--- here

Should have been grouped on either ('NAME', 'on_post_save_async') (before) or ('NAME', 'called') (after) token.

During handling of the above exception, another exception occurred:

Traceback (most recent call last):
  File "/Users/cbono/Library/Application Support/Sublime Text 3/Packages/User/codehealth.py", line 245, in render_health_scores
    cs = compare(HealthCommand.last_file_contents, current_text)
  File "/Users/cbono/Library/Application Support/Sublime Text 3/Packages/User/compare.py", line 106, in compare
    result = [r for r in result if r != []]
NameError: global name 'print_to_log' is not defined

Traceback (most recent call last):
  File "/Users/cbono/Library/Application Support/Sublime Text 3/Packages/User/compare.py", line 70, in compare
  File "/Library/Frameworks/Python.framework/Versions/3.5/lib/python3.5/site-packages/redbaron/redbaron.py", line 36, in __init__
    self.node_list = base_nodes.NodeList.from_fst(baron.parse(source_code), parent=self, on_attribute="root")
  File "/Library/Frameworks/Python.framework/Versions/3.5/lib/python3.5/site-packages/baron/baron.py", line 49, in parse
    tokens = tokenize(source_code, False)
  File "/Library/Frameworks/Python.framework/Versions/3.5/lib/python3.5/site-packages/baron/baron.py", line 70, in tokenize
    return mark_indentation(inner_group(space_group(_tokenize(group(split(pouet)), print_function))))
  File "/Library/Frameworks/Python.framework/Versions/3.5/lib/python3.5/site-packages/baron/inner_formatting_grouper.py", line 112, in group
    return list(group_generator(sequence))
  File "/Library/Frameworks/Python.framework/Versions/3.5/lib/python3.5/site-packages/baron/inner_formatting_grouper.py", line 189, in group_generator
    raise UnExpectedFormattingToken(debug_text)
baron.inner_formatting_grouper.UnExpectedFormattingToken: Unexpected 'space' token:

   1 on_post_save_async <--- here

Should have been grouped on either ('NAME', 'on_post_save_async') (before) or ('NAME', 'called') (after) token.

During handling of the above exception, another exception occurred:

Traceback (most recent call last):
  File "/Users/cbono/Library/Application Support/Sublime Text 3/Packages/User/codehealth.py", line 245, in render_health_scores
    cs = compare(HealthCommand.last_file_contents, current_text)
  File "/Users/cbono/Library/Application Support/Sublime Text 3/Packages/User/compare.py", line 106, in compare
    result = [r for r in result if r != []]
NameError: global name 'print_to_log' is not defined

Traceback (most recent call last):
  File "/Users/cbono/Library/Application Support/Sublime Text 3/Packages/User/compare.py", line 70, in compare
  File "/Library/Frameworks/Python.framework/Versions/3.5/lib/python3.5/site-packages/redbaron/redbaron.py", line 36, in __init__
    self.node_list = base_nodes.NodeList.from_fst(baron.parse(source_code), parent=self, on_attribute="root")
  File "/Library/Frameworks/Python.framework/Versions/3.5/lib/python3.5/site-packages/baron/baron.py", line 49, in parse
    tokens = tokenize(source_code, False)
  File "/Library/Frameworks/Python.framework/Versions/3.5/lib/python3.5/site-packages/baron/baron.py", line 70, in tokenize
    return mark_indentation(inner_group(space_group(_tokenize(group(split(pouet)), print_function))))
  File "/Library/Frameworks/Python.framework/Versions/3.5/lib/python3.5/site-packages/baron/inner_formatting_grouper.py", line 112, in group
    return list(group_generator(sequence))
  File "/Library/Frameworks/Python.framework/Versions/3.5/lib/python3.5/site-packages/baron/inner_formatting_grouper.py", line 189, in group_generator
    raise UnExpectedFormattingToken(debug_text)
baron.inner_formatting_grouper.UnExpectedFormattingToken: Unexpected 'space' token:

   1 on_post_save_async <--- here

Should have been grouped on either ('NAME', 'on_post_save_async') (before) or ('NAME', 'called') (after) token.

During handling of the above exception, another exception occurred:

Traceback (most recent call last):
  File "/Users/cbono/Library/Application Support/Sublime Text 3/Packages/User/codehealth.py", line 245, in render_health_scores
    cs = compare(HealthCommand.last_file_contents, current_text)
  File "/Users/cbono/Library/Application Support/Sublime Text 3/Packages/User/compare.py", line 106, in compare
    result = [r for r in result if r != []]
NameError: global name 'print_to_log' is not defined

Traceback (most recent call last):
  File "/Users/cbono/Library/Application Support/Sublime Text 3/Packages/User/compare.py", line 70, in compare
  File "/Library/Frameworks/Python.framework/Versions/3.5/lib/python3.5/site-packages/redbaron/redbaron.py", line 36, in __init__
    self.node_list = base_nodes.NodeList.from_fst(baron.parse(source_code), parent=self, on_attribute="root")
  File "/Library/Frameworks/Python.framework/Versions/3.5/lib/python3.5/site-packages/baron/baron.py", line 49, in parse
    tokens = tokenize(source_code, False)
  File "/Library/Frameworks/Python.framework/Versions/3.5/lib/python3.5/site-packages/baron/baron.py", line 70, in tokenize
    return mark_indentation(inner_group(space_group(_tokenize(group(split(pouet)), print_function))))
  File "/Library/Frameworks/Python.framework/Versions/3.5/lib/python3.5/site-packages/baron/inner_formatting_grouper.py", line 112, in group
    return list(group_generator(sequence))
  File "/Library/Frameworks/Python.framework/Versions/3.5/lib/python3.5/site-packages/baron/inner_formatting_grouper.py", line 189, in group_generator
    raise UnExpectedFormattingToken(debug_text)
baron.inner_formatting_grouper.UnExpectedFormattingToken: Unexpected 'space' token:

   1 on_post_save_async <--- here

Should have been grouped on either ('NAME', 'on_post_save_async') (before) or ('NAME', 'called') (after) token.

During handling of the above exception, another exception occurred:

Traceback (most recent call last):
  File "/Users/cbono/Library/Application Support/Sublime Text 3/Packages/User/codehealth.py", line 245, in render_health_scores
    cs = compare(HealthCommand.last_file_contents, current_text)
  File "/Users/cbono/Library/Application Support/Sublime Text 3/Packages/User/compare.py", line 106, in compare
    result = [r for r in result if r != []]
NameError: global name 'print_to_log' is not defined

Traceback (most recent call last):
  File "/Users/cbono/Library/Application Support/Sublime Text 3/Packages/User/compare.py", line 70, in compare
  File "/Library/Frameworks/Python.framework/Versions/3.5/lib/python3.5/site-packages/redbaron/redbaron.py", line 36, in __init__
    self.node_list = base_nodes.NodeList.from_fst(baron.parse(source_code), parent=self, on_attribute="root")
  File "/Library/Frameworks/Python.framework/Versions/3.5/lib/python3.5/site-packages/baron/baron.py", line 49, in parse
    tokens = tokenize(source_code, False)
  File "/Library/Frameworks/Python.framework/Versions/3.5/lib/python3.5/site-packages/baron/baron.py", line 70, in tokenize
    return mark_indentation(inner_group(space_group(_tokenize(group(split(pouet)), print_function))))
  File "/Library/Frameworks/Python.framework/Versions/3.5/lib/python3.5/site-packages/baron/inner_formatting_grouper.py", line 112, in group
    return list(group_generator(sequence))
  File "/Library/Frameworks/Python.framework/Versions/3.5/lib/python3.5/site-packages/baron/inner_formatting_grouper.py", line 189, in group_generator
    raise UnExpectedFormattingToken(debug_text)
baron.inner_formatting_grouper.UnExpectedFormattingToken: Unexpected 'space' token:

   1 on_post_save_async <--- here

Should have been grouped on either ('NAME', 'on_post_save_async') (before) or ('NAME', 'called') (after) token.

During handling of the above exception, another exception occurred:

Traceback (most recent call last):
  File "/Users/cbono/Library/Application Support/Sublime Text 3/Packages/User/codehealth.py", line 245, in render_health_scores
    cs = compare(HealthCommand.last_file_contents, current_text)
  File "/Users/cbono/Library/Application Support/Sublime Text 3/Packages/User/compare.py", line 106, in compare
    result = [r for r in result if r != []]
NameError: global name 'print_to_log' is not defined

Traceback (most recent call last):
  File "/Users/cbono/Library/Application Support/Sublime Text 3/Packages/User/compare.py", line 70, in compare
  File "/Library/Frameworks/Python.framework/Versions/3.5/lib/python3.5/site-packages/redbaron/redbaron.py", line 36, in __init__
    self.node_list = base_nodes.NodeList.from_fst(baron.parse(source_code), parent=self, on_attribute="root")
  File "/Library/Frameworks/Python.framework/Versions/3.5/lib/python3.5/site-packages/baron/baron.py", line 49, in parse
    tokens = tokenize(source_code, False)
  File "/Library/Frameworks/Python.framework/Versions/3.5/lib/python3.5/site-packages/baron/baron.py", line 70, in tokenize
    return mark_indentation(inner_group(space_group(_tokenize(group(split(pouet)), print_function))))
  File "/Library/Frameworks/Python.framework/Versions/3.5/lib/python3.5/site-packages/baron/inner_formatting_grouper.py", line 112, in group
    return list(group_generator(sequence))
  File "/Library/Frameworks/Python.framework/Versions/3.5/lib/python3.5/site-packages/baron/inner_formatting_grouper.py", line 189, in group_generator
    raise UnExpectedFormattingToken(debug_text)
baron.inner_formatting_grouper.UnExpectedFormattingToken: Unexpected 'space' token:

   1 on_post_save_async <--- here

Should have been grouped on either ('NAME', 'on_post_save_async') (before) or ('NAME', 'called') (after) token.

During handling of the above exception, another exception occurred:

Traceback (most recent call last):
  File "/Users/cbono/Library/Application Support/Sublime Text 3/Packages/User/codehealth.py", line 245, in render_health_scores
    cs = compare(HealthCommand.last_file_contents, current_text)
  File "/Users/cbono/Library/Application Support/Sublime Text 3/Packages/User/compare.py", line 106, in compare
    result = [r for r in result if r != []]
NameError: global name 'print_to_log' is not defined

Traceback (most recent call last):
  File "/Users/cbono/Library/Application Support/Sublime Text 3/Packages/User/compare.py", line 70, in compare
  File "/Library/Frameworks/Python.framework/Versions/3.5/lib/python3.5/site-packages/redbaron/redbaron.py", line 36, in __init__
    self.node_list = base_nodes.NodeList.from_fst(baron.parse(source_code), parent=self, on_attribute="root")
  File "/Library/Frameworks/Python.framework/Versions/3.5/lib/python3.5/site-packages/baron/baron.py", line 49, in parse
    tokens = tokenize(source_code, False)
  File "/Library/Frameworks/Python.framework/Versions/3.5/lib/python3.5/site-packages/baron/baron.py", line 70, in tokenize
    return mark_indentation(inner_group(space_group(_tokenize(group(split(pouet)), print_function))))
  File "/Library/Frameworks/Python.framework/Versions/3.5/lib/python3.5/site-packages/baron/inner_formatting_grouper.py", line 112, in group
    return list(group_generator(sequence))
  File "/Library/Frameworks/Python.framework/Versions/3.5/lib/python3.5/site-packages/baron/inner_formatting_grouper.py", line 189, in group_generator
    raise UnExpectedFormattingToken(debug_text)
baron.inner_formatting_grouper.UnExpectedFormattingToken: Unexpected 'space' token:

   1 on_post_save_async <--- here

Should have been grouped on either ('NAME', 'on_post_save_async') (before) or ('NAME', 'called') (after) token.

During handling of the above exception, another exception occurred:

Traceback (most recent call last):
  File "/Users/cbono/Library/Application Support/Sublime Text 3/Packages/User/codehealth.py", line 245, in render_health_scores
    cs = compare(HealthCommand.last_file_contents, current_text)
  File "/Users/cbono/Library/Application Support/Sublime Text 3/Packages/User/compare.py", line 106, in compare
    result = [r for r in result if r != []]
NameError: global name 'print_to_log' is not defined

Traceback (most recent call last):
  File "/Users/cbono/Library/Application Support/Sublime Text 3/Packages/User/compare.py", line 70, in compare
  File "/Library/Frameworks/Python.framework/Versions/3.5/lib/python3.5/site-packages/redbaron/redbaron.py", line 36, in __init__
    self.node_list = base_nodes.NodeList.from_fst(baron.parse(source_code), parent=self, on_attribute="root")
  File "/Library/Frameworks/Python.framework/Versions/3.5/lib/python3.5/site-packages/baron/baron.py", line 49, in parse
    tokens = tokenize(source_code, False)
  File "/Library/Frameworks/Python.framework/Versions/3.5/lib/python3.5/site-packages/baron/baron.py", line 70, in tokenize
    return mark_indentation(inner_group(space_group(_tokenize(group(split(pouet)), print_function))))
  File "/Library/Frameworks/Python.framework/Versions/3.5/lib/python3.5/site-packages/baron/inner_formatting_grouper.py", line 112, in group
    return list(group_generator(sequence))
  File "/Library/Frameworks/Python.framework/Versions/3.5/lib/python3.5/site-packages/baron/inner_formatting_grouper.py", line 189, in group_generator
    raise UnExpectedFormattingToken(debug_text)
baron.inner_formatting_grouper.UnExpectedFormattingToken: Unexpected 'space' token:

   1 on_post_save_async <--- here

Should have been grouped on either ('NAME', 'on_post_save_async') (before) or ('NAME', 'called') (after) token.

During handling of the above exception, another exception occurred:

Traceback (most recent call last):
  File "/Users/cbono/Library/Application Support/Sublime Text 3/Packages/User/codehealth.py", line 245, in render_health_scores
    cs = compare(HealthCommand.last_file_contents, current_text)
  File "/Users/cbono/Library/Application Support/Sublime Text 3/Packages/User/compare.py", line 106, in compare
    result = [r for r in result if r != []]
NameError: global name 'print_to_log' is not defined

Activate Health
Remove Health
Remove Health
Remove Health
Remove Health
Remove Health
on_post_save_async called
on_post_save_async called
on_post_save_async called
on_post_save_async called
loading contents: /Users/cbono/Documents/code/codehealth/codehealth_ln.py
get_head_contents - codehealth_ln.py True
cmd: git show HEAD:codehealth_ln.py
setup successful
Traceback (most recent call last):
  File "/Users/cbono/Library/Application Support/Sublime Text 3/Packages/User/compare.py", line 69, in compare
    red1 = RedBaron(s1)
  File "/Library/Frameworks/Python.framework/Versions/3.5/lib/python3.5/site-packages/redbaron/redbaron.py", line 36, in __init__
    self.node_list = base_nodes.NodeList.from_fst(baron.parse(source_code), parent=self, on_attribute="root")
  File "/Library/Frameworks/Python.framework/Versions/3.5/lib/python3.5/site-packages/baron/baron.py", line 49, in parse
    tokens = tokenize(source_code, False)
  File "/Library/Frameworks/Python.framework/Versions/3.5/lib/python3.5/site-packages/baron/baron.py", line 70, in tokenize
    return mark_indentation(inner_group(space_group(_tokenize(group(split(pouet)), print_function))))
  File "/Library/Frameworks/Python.framework/Versions/3.5/lib/python3.5/site-packages/baron/inner_formatting_grouper.py", line 112, in group
    return list(group_generator(sequence))
  File "/Library/Frameworks/Python.framework/Versions/3.5/lib/python3.5/site-packages/baron/inner_formatting_grouper.py", line 189, in group_generator
    raise UnExpectedFormattingToken(debug_text)
baron.inner_formatting_grouper.UnExpectedFormattingToken: Unexpected 'space' token:

   1 /Users/cbono/Library/Application <--- here

Should have been grouped on either ('NAME', 'Application') (before) or ('NAME', 'Support') (after) token.

During handling of the above exception, another exception occurred:

Traceback (most recent call last):
  File "/Users/cbono/Library/Application Support/Sublime Text 3/Packages/User/codehealth.py", line 245, in render_health_scores
    cs = compare(HealthCommand.last_file_contents, current_text)
  File "/Users/cbono/Library/Application Support/Sublime Text 3/Packages/User/compare.py", line 106, in compare
    return []
NameError: global name 'print_to_log' is not defined

loading contents: /Users/cbono/Documents/code/codehealth/log.txt
get_head_contents - log.txt False
setup successful
on_post_save_async called
on_post_save_async called
loading contents: /Users/cbono/Documents/code/codehealth/compare.py
get_head_contents - compare.py True
cmd: git show HEAD:compare.py
setup successful
<Comment left_bounds:(39, 19) right_bounds:(39, 87) score:86>
<Comment left_bounds:(104, 9) right_bounds:(104, 37) score:0>
